Workbook
Name Slicer_Month: #N/A

Sheet Dashbord
B1: colors
AA9: 4
F14: #VALUE!

Sheet Budegting
AA9: 4
F14: #VALUE!

Sheet Investmants
B1: colors
AA9: 4
F14: #VALUE!

Sheet Debts
B1: colors
AA9: 4
F14: #VALUE!

Sheet Fin Goals
B1: colors
AA9: 4
F14: #VALUE!

Sheet Processing
A1: Month | B1: X | C1: indent | D1: Income | E1: Expenses | F1: indent C | G1: Cursor I | H1: Cursor e | I1: Markar | J1: Labele | K1: Month | L1: Ratio | M1: Ratio incom | O1: X | P1: Y
A2: JANUARY | B2: =LEFT(A2,3) -> JAN | C2: =$C$14 -> 1394.8 | D2: =GETPIVOTDATA(""&D$1,Control!$A$20,"Month",""&$A2) -> 17800 | E2: =GETPIVOTDATA(""&E$1,Control!$A$20,"Month",""&$A2) -> 18904 | F2: =C2 -> 1394.8 | G2: =IFERROR(GETPIVOTDATA(""&D$1,Control!$A$3,"Month",""&$A2),(NA())) -> 17800 | H2: =IFERROR(GETPIVOTDATA(""&E$1,Control!$A$3,"Month",""&$A2),(NA())) -> 18904 | I2: =C2+G2 -> 19194.8 | J2: =IF(G2>=1000,TEXT(ROUND(G2/1000,0),"0k"),G2) -> 18k | K2: =GETPIVOTDATA("Max of Month N",Control!$A$3) -> 1 | L2: =D2/SUM(D2:E2) -> 0.48496077 | M2: {=INDEX(L2:L13,K2)} -> 0.48496077 | N2: =1-M2 -> 0.51503923 | O2: 0 | P2: 1
A3: FEBRUARY | B3: =LEFT(A3,3) -> FEB | C3: =$C$14 -> 1394.8 | D3: =GETPIVOTDATA(""&D$1,Control!$A$20,"Month",""&$A3) -> 18080 | E3: =GETPIVOTDATA(""&E$1,Control!$A$20,"Month",""&$A3) -> 18279 | F3: =C3 -> 1394.8 | G3: =IFERROR(GETPIVOTDATA(""&D$1,Control!$A$3,"Month",""&$A3),(NA())) -> #N/A | H3: =IFERROR(GETPIVOTDATA(""&E$1,Control!$A$3,"Month",""&$A3),(NA())) -> #N/A | I3: =C3+G3 -> #N/A | J3: =IF(G3>=1000,TEXT(ROUND(G3/1000,0),"0k"),G3) -> #N/A | L3: =D3/SUM(D3:E3) -> 0.4972634 | O3: =SIN(M2*2*PI()) -> 0.094353723 | P3: =COS(N2*2*PI()) -> -0.99553874
A4: MARCH | B4: =LEFT(A4,3) -> MAR | C4: =$C$14 -> 1394.8 | D4: =GETPIVOTDATA(""&D$1,Control!$A$20,"Month",""&$A4) -> 20857 | E4: =GETPIVOTDATA(""&E$1,Control!$A$20,"Month",""&$A4) -> 20177 | F4: =C4 -> 1394.8 | G4: =IFERROR(GETPIVOTDATA(""&D$1,Control!$A$3,"Month",""&$A4),(NA())) -> #N/A | H4: =IFERROR(GETPIVOTDATA(""&E$1,Control!$A$3,"Month",""&$A4),(NA())) -> #N/A | I4: =C4+G4 -> #N/A | J4: =IF(G4>=1000,TEXT(ROUND(G4/1000,0),"0k"),G4) -> #N/A | L4: =D4/SUM(D4:E4) -> 0.50828581
A5: APRIL | B5: =LEFT(A5,3) -> APR | C5: =$C$14 -> 1394.8 | D5: =GETPIVOTDATA(""&D$1,Control!$A$20,"Month",""&$A5) -> 21688 | E5: =GETPIVOTDATA(""&E$1,Control!$A$20,"Month",""&$A5) -> 20154 | F5: =C5 -> 1394.8 | G5: =IFERROR(GETPIVOTDATA(""&D$1,Control!$A$3,"Month",""&$A5),(NA())) -> #N/A | H5: =IFERROR(GETPIVOTDATA(""&E$1,Control!$A$3,"Month",""&$A5),(NA())) -> #N/A | I5: =C5+G5 -> #N/A | J5: =IF(G5>=1000,TEXT(ROUND(G5/1000,0),"0k"),G5) -> #N/A | K5: Balance | L5: =D5/SUM(D5:E5) -> 0.51833086
A6: MAY | B6: =LEFT(A6,3) -> MAY | C6: =$C$14 -> 1394.8 | D6: =GETPIVOTDATA(""&D$1,Control!$A$20,"Month",""&$A6) -> 23965 | E6: =GETPIVOTDATA(""&E$1,Control!$A$20,"Month",""&$A6) -> 21472 | F6: =C6 -> 1394.8 | G6: =IFERROR(GETPIVOTDATA(""&D$1,Control!$A$3,"Month",""&$A6),(NA())) -> #N/A | H6: =IFERROR(GETPIVOTDATA(""&E$1,Control!$A$3,"Month",""&$A6),(NA())) -> #N/A | I6: =C6+G6 -> #N/A | J6: =IF(G6>=1000,TEXT(ROUND(G6/1000,0),"0k"),G6) -> #N/A | K6: =GETPIVOTDATA("Average of Balance",Control!$A$3) -> 3980.3871 | L6: =D6/SUM(D6:E6) -> 0.52743359
A7: JUNE | B7: =LEFT(A7,3) -> JUN | C7: =$C$14 -> 1394.8 | D7: =GETPIVOTDATA(""&D$1,Control!$A$20,"Month",""&$A7) -> 24696 | E7: =GETPIVOTDATA(""&E$1,Control!$A$20,"Month",""&$A7) -> 21406 | F7: =C7 -> 1394.8 | G7: =IFERROR(GETPIVOTDATA(""&D$1,Control!$A$3,"Month",""&$A7),(NA())) -> #N/A | H7: =IFERROR(GETPIVOTDATA(""&E$1,Control!$A$3,"Month",""&$A7),(NA())) -> #N/A | I7: =C7+G7 -> #N/A | J7: =IF(G7>=1000,TEXT(ROUND(G7/1000,0),"0k"),G7) -> #N/A | L7: =D7/SUM(D7:E7) -> 0.53568175
A8: JULY | B8: =LEFT(A8,3) -> JUL | C8: =$C$14 -> 1394.8 | D8: =GETPIVOTDATA(""&D$1,Control!$A$20,"Month",""&$A8) -> 27073 | E8: =GETPIVOTDATA(""&E$1,Control!$A$20,"Month",""&$A8) -> 22768 | F8: =C8 -> 1394.8 | G8: =IFERROR(GETPIVOTDATA(""&D$1,Control!$A$3,"Month",""&$A8),(NA())) -> #N/A | H8: =IFERROR(GETPIVOTDATA(""&E$1,Control!$A$3,"Month",""&$A8),(NA())) -> #N/A | I8: =C8+G8 -> #N/A | J8: =IF(G8>=1000,TEXT(ROUND(G8/1000,0),"0k"),G8) -> #N/A | L8: =D8/SUM(D8:E8) -> 0.54318734
A9: AUGUST | B9: =LEFT(A9,3) -> AUG | C9: =$C$14 -> 1394.8 | D9: =GETPIVOTDATA(""&D$1,Control!$A$20,"Month",""&$A9) -> 28654 | E9: =GETPIVOTDATA(""&E$1,Control!$A$20,"Month",""&$A9) -> 23426 | F9: =C9 -> 1394.8 | G9: =IFERROR(GETPIVOTDATA(""&D$1,Control!$A$3,"Month",""&$A9),(NA())) -> #N/A | H9: =IFERROR(GETPIVOTDATA(""&E$1,Control!$A$3,"Month",""&$A9),(NA())) -> #N/A | I9: =C9+G9 -> #N/A | J9: =IF(G9>=1000,TEXT(ROUND(G9/1000,0),"0k"),G9) -> #N/A | L9: =D9/SUM(D9:E9) -> 0.55019201
A10: SEPTEMBER | B10: =LEFT(A10,3) -> SEP | C10: =$C$14 -> 1394.8 | D10: =GETPIVOTDATA(""&D$1,Control!$A$20,"Month",""&$A10) -> 29233 | E10: =GETPIVOTDATA(""&E$1,Control!$A$20,"Month",""&$A10) -> 23296 | F10: =C10 -> 1394.8 | G10: =IFERROR(GETPIVOTDATA(""&D$1,Control!$A$3,"Month",""&$A10),(NA())) -> #N/A | H10: =IFERROR(GETPIVOTDATA(""&E$1,Control!$A$3,"Month",""&$A10),(NA())) -> #N/A | I10: =C10+G10 -> #N/A | J10: =IF(G10>=1000,TEXT(ROUND(G10/1000,0),"0k"),G10) -> #N/A | L10: =D10/SUM(D10:E10) -> 0.55651164
A11: OCTOBER | B11: =LEFT(A11,3) -> OCT | C11: =$C$14 -> 1394.8 | D11: =GETPIVOTDATA(""&D$1,Control!$A$20,"Month",""&$A11) -> 31762 | E11: =GETPIVOTDATA(""&E$1,Control!$A$20,"Month",""&$A11) -> 24722 | F11: =C11 -> 1394.8 | G11: =IFERROR(GETPIVOTDATA(""&D$1,Control!$A$3,"Month",""&$A11),(NA())) -> #N/A | H11: =IFERROR(GETPIVOTDATA(""&E$1,Control!$A$3,"Month",""&$A11),(NA())) -> #N/A | I11: =C11+G11 -> #N/A | J11: =IF(G11>=1000,TEXT(ROUND(G11/1000,0),"0k"),G11) -> #N/A | L11: =D11/SUM(D11:E11) -> 0.56231853
A12: NOVEMBER | B12: =LEFT(A12,3) -> NOV | C12: =$C$14 -> 1394.8 | D12: =GETPIVOTDATA(""&D$1,Control!$A$20,"Month",""&$A12) -> 32242 | E12: =GETPIVOTDATA(""&E$1,Control!$A$20,"Month",""&$A12) -> 24550 | F12: =C12 -> 1394.8 | G12: =IFERROR(GETPIVOTDATA(""&D$1,Control!$A$3,"Month",""&$A12),(NA())) -> #N/A | H12: =IFERROR(GETPIVOTDATA(""&E$1,Control!$A$3,"Month",""&$A12),(NA())) -> #N/A | I12: =C12+G12 -> #N/A | J12: =IF(G12>=1000,TEXT(ROUND(G12/1000,0),"0k"),G12) -> #N/A | L12: =D12/SUM(D12:E12) -> 0.56772081
A13: DECEMBER | B13: =LEFT(A13,3) -> DEC | C13: =$C$14 -> 1394.8 | D13: =GETPIVOTDATA(""&D$1,Control!$A$20,"Month",""&$A13) -> 34870 | E13: =GETPIVOTDATA(""&E$1,Control!$A$20,"Month",""&$A13) -> 26016 | F13: =C13 -> 1394.8 | G13: =IFERROR(GETPIVOTDATA(""&D$1,Control!$A$3,"Month",""&$A13),(NA())) -> #N/A | H13: =IFERROR(GETPIVOTDATA(""&E$1,Control!$A$3,"Month",""&$A13),(NA())) -> #N/A | I13: =C13+G13 -> #N/A | J13: =IF(G13>=1000,TEXT(ROUND(G13/1000,0),"0k"),G13) -> #N/A | L13: =D13/SUM(D13:E13) -> 0.57270965 | M13: =E13/SUM(E13:F13) -> 0.94911495
C14: =MAX(D2:E13)*4% -> 1394.8 | D14: =GETPIVOTDATA("Sum of Income",Control!$A$3) -> 17800 | E14: =GETPIVOTDATA("Sum of Expenses",Control!$A$3) -> 18904
M15: Debts | N15: Iterest Ratr
A16: Budegt | B16: =B17-A27 -> 281096 | M16: Mortgage | N16: 0.03 | O16: =GETPIVOTDATA(""&M16,Control!$A$3) -> 27.354839
A17: Budget Plan | B17: 300000 | E17: Budgetig | M17: Car Leasing | N17: 0.1 | O17: =GETPIVOTDATA(""&M17,Control!$A$3) -> 19
A18: Non-Fixed Incom | B18: =GETPIVOTDATA(""&A18,Control!$A$3) -> 811 | C18: =B18/SUM($B$24:$B$25) -> 0.18208352 | E18: {=TRANSPOSE(C18:C23)} -> 0.18208352 | F18: 0.15469241 | G18: 0.18230804 | H18: 0.17220476 | I18: 0.15087562 | J18: 0.15783565 | M18: Consumer Credit | N18: 0.05 | O18: =GETPIVOTDATA(""&M18,Control!$A$3) -> 22.741935
A19: Fixed Incom | B19: =GETPIVOTDATA(""&A19,Control!$A$3) -> 689 | C19: =B19/SUM($B$24:$B$25) -> 0.15469241 | E19: =E18 -> 0.18208352 | F19: =F18 -> 0.15469241 | G19: =G18 -> 0.18230804 | H19: =H18 -> 0.17220476 | I19: =I18 -> 0.15087562 | J19: =J18 -> 0.15783565 | M19: Credit Card | N19: 0.07 | O19: =GETPIVOTDATA(""&M19,Control!$A$3) -> 26.322581
A20: Other Income | B20: =GETPIVOTDATA(""&A20,Control!$A$3) -> 812 | C20: =B20/SUM($B$24:$B$25) -> 0.18230804 | E20: =E19 -> 0.18208352 | F20: =F19 -> 0.15469241 | G20: =G19 -> 0.18230804 | H20: =H19 -> 0.17220476 | I20: =I19 -> 0.15087562 | J20: =J19 -> 0.15783565 | O20: =SUM(O16:O19) -> 95.419355
A21: Non-Fixed Cost | B21: =GETPIVOTDATA(""&A21,Control!$A$3) -> 767 | C21: =B21/SUM($B$24:$B$25) -> 0.17220476
A22: Fixed Costs | B22: =GETPIVOTDATA(""&A22,Control!$A$3) -> 672 | C22: =B22/SUM($B$24:$B$25) -> 0.15087562
A23: Other Cost | B23: =GETPIVOTDATA(""&A23,Control!$A$3) -> 703 | C23: =B23/SUM($B$24:$B$25) -> 0.15783565
A24: Total Income | B24: =SUM(B18:B20) -> 2312 | F24: Investments | G24: Invest | H24: =SUM(G25:G29) -> 121.12903 | M24: Labels
A25: Total Cost | B25: =SUM(B21:B23) -> 2142 | F25: Investments Business | G25: =GETPIVOTDATA(""&F25,Control!$A$3) -> 24.354839 | H25: =G25/$H$24 -> 0.20106525 | I25: =H25 -> 0.20106525 | J25: =I25 -> 0.20106525 | K25: =J25 -> 0.20106525 | L25: =K25 -> 0.20106525 | M25: Business
A26: Used Budegt | B26: =SUM(E2:INDEX(E2:E13,K2))/B17 -> 0.063013333 | C26: =1-B26 -> 0.93698667 | F26: Investments Securities | G26: =GETPIVOTDATA(""&F26,Control!$A$3) -> 28.903226 | H26: =G26/$H$24 -> 0.23861518 | I26: =H26 -> 0.23861518 | J26: =I26 -> 0.23861518 | K26: =J26 -> 0.23861518 | L26: =K26 -> 0.23861518 | M26: Securities
A27: =B17*B26 -> 18904 | F27: Investments Cryptocurrency | G27: =GETPIVOTDATA(""&F27,Control!$A$3) -> 21.677419 | H27: =G27/$H$24 -> 0.17896138 | I27: =H27 -> 0.17896138 | J27: =I27 -> 0.17896138 | K27: =J27 -> 0.17896138 | L27: =K27 -> 0.17896138 | M27: Crypto
F28: Investments Real estate | G28: =GETPIVOTDATA(""&F28,Control!$A$3) -> 23.709677 | H28: =G28/$H$24 -> 0.19573901 | I28: =H28 -> 0.19573901 | J28: =I28 -> 0.19573901 | K28: =J28 -> 0.19573901 | L28: =K28 -> 0.19573901 | M28: Rent
F29: Investments Gold | G29: =GETPIVOTDATA(""&F29,Control!$A$3) -> 22.483871 | H29: =G29/$H$24 -> 0.18561917 | I29: =H29 -> 0.18561917 | J29: =I29 -> 0.18561917 | K29: =J29 -> 0.18561917 | L29: =K29 -> 0.18561917 | M29: Gold
H30: 1 | I30: 1 | J30: 1 | K30: 1 | L30: 1
A34: Implemntaion | B34: Goal 1 | C34: Goal 2 | D34: Goal 3 | E34: Goal 4 | F34: Total
A35: Done | B35: =GETPIVOTDATA(""&B34,Control!$A$3) -> 21.774194 | C35: =GETPIVOTDATA(""&C34,Control!$A$3) -> 26.483871 | D35: =GETPIVOTDATA(""&D34,Control!$A$3) -> 22.451613 | E35: =GETPIVOTDATA(""&E34,Control!$A$3) -> 27.935484 | F35: =SUM(B35:E35) -> 98.645161
A36: Left | B36: =B37-B35 -> 58.225806 | C36: =C37-C35 -> 43.516129 | D36: =D37-D35 -> 42.548387 | E36: =E37-E35 -> 12.064516 | F36: =SUM(B36:E36) -> 156.35484
A37: Plan | B37: 80 | C37: 70 | D37: 65 | E37: 40 | F37: =SUM(B37:E37) -> 255
A38: Done % | B38: =B35/B37 -> 0.27217742 | C38: =C35/C37 -> 0.37834101 | D38: =D35/D37 -> 0.34540943 | E38: =E35/E37 -> 0.6983871 | F38: =F35/F37 -> 0.38684377
A39: Goals % | B39: =B37/$B$40 -> 1 | C39: =C37/$B$40 -> 0.875 | D39: =D37/$B$40 -> 0.8125 | E39: =E37/$B$40 -> 0.5 | F39: =1-F38 -> 0.61315623
A40: MAX Plan | B40: =MAX(B37:E37) -> 80
B42: Goal 4 | D42: Goal 3 | F42: Goal 2 | H42: Goal 1 | I42: Sectors
A43: Done | B43: {=(100%-SUM(B45:B46))*INDEX($B$38:$E$38,1,B47)} -> 0.26189516 | C43: {=(100%-SUM(C45:C46))*INDEX($B$38:$E$38,1,C47)} -> 0.26189516 | D43: {=(100%-SUM(D45:D46))*INDEX($B$38:$E$38,1,D47)} -> 0.21048387 | E43: {=(100%-SUM(E45:E46))*INDEX($B$38:$E$38,1,E47)} -> 0.21048387 | F43: {=(100%-SUM(F45:F46))*INDEX($B$38:$E$38,1,F47)} -> 0.24828629 | G43: {=(100%-SUM(G45:G46))*INDEX($B$38:$E$38,1,G47)} -> 0.24828629 | H43: {=(100%-SUM(H45:H46))*INDEX($B$38:$E$38,1,H47)} -> 0.20413306 | I43: 0.75
A44: Running | B44: =100%-SUM(B45:B46)-B43 -> 0.11310484 | C44: =100%-SUM(C45:C46)-C43 -> 0.11310484 | D44: =100%-SUM(D45:D46)-D43 -> 0.39889113 | E44: =100%-SUM(E45:E46)-E43 -> 0.39889113 | F44: =100%-SUM(F45:F46)-F43 -> 0.40796371 | G44: =100%-SUM(G45:G46)-G43 -> 0.40796371 | H44: =100%-SUM(H45:H46)-H43 -> 0.54586694 | I44: 0
...

Sheet Control
A3: Row Labels | B3: Max of Month N | C3: Sum of Income | D3: Sum of Expenses | E3: Average of Balance | F3: Sum of Non-Fixed Incom | G3: Sum of Fixed Incom | H3: Sum of Other Income | I3: Sum of Non-Fixed Cost | J3: Sum of Fixed Costs | K3: Sum of Other Cost | L3: Average of Investments Business | M3: Average of Investments Securities | N3: Average of Investments Cryptocurrency | O3: Average of Investments Real estate | P3: Average of Investments Gold | Q3: Average of Mortgage | R3: Average of Car Leasing | S3: Average of Consumer Credit | T3: Average of Credit Card | U3: Average of Goal 1 | V3: Average of Goal 2 | W3: Average of Goal 3 | X3: Average of Goal 4
A4: JANUARY | B4: 1 | C4: 17800 | D4: 18904 | E4: 3980.3871 | F4: 811 | G4: 689 | H4: 812 | I4: 767 | J4: 672 | K4: 703 | L4: 24.354839 | M4: 28.903226 | N4: 21.677419 | O4: 23.709677 | P4: 22.483871 | Q4: 27.354839 | R4: 19 | S4: 22.741935 | T4: 26.322581 | U4: 21.774194 | V4: 26.483871 | W4: 22.451613 | X4: 27.935484
A5: Grand Total | B5: 1 | C5: 17800 | D5: 18904 | E5: 3980.3871 | F5: 811 | G5: 689 | H5: 812 | I5: 767 | J5: 672 | K5: 703 | L5: 24.354839 | M5: 28.903226 | N5: 21.677419 | O5: 23.709677 | P5: 22.483871 | Q5: 27.354839 | R5: 19 | S5: 22.741935 | T5: 26.322581 | U5: 21.774194 | V5: 26.483871 | W5: 22.451613 | X5: 27.935484
A20: Row Labels | B20: Sum of Income | C20: Sum of Expenses
A21: JANUARY | B21: 17800 | C21: 18904
A22: FEBRUARY | B22: 18080 | C22: 18279
A23: MARCH | B23: 20857 | C23: 20177
A24: APRIL | B24: 21688 | C24: 20154
A25: MAY | B25: 23965 | C25: 21472
A26: JUNE | B26: 24696 | C26: 21406
A27: JULY | B27: 27073 | C27: 22768
A28: AUGUST | B28: 28654 | C28: 23426
A29: SEPTEMBER | B29: 29233 | C29: 23296
A30: OCTOBER | B30: 31762 | C30: 24722
A31: NOVEMBER | B31: 32242 | C31: 24550
A32: DECEMBER | B32: 34870 | C32: 26016
A33: Grand Total | B33: 310920 | C33: 265170

Sheet Data
A1: Date | B1: Month | C1: Month N | D1: Income | E1: Expenses | F1: Non-Fixed Incom | G1: Fixed Incom | H1: Other Income | I1: Non-Fixed Cost | J1: Fixed Costs | K1: Other Cost | L1: Fixed Incom Business | M1: Fixed Incom Securities | N1: Fixed Incom Real estate | O1: Fixed Incom Gold | P1: Fixed Incom Cryptocurrency | Q1: Loans | R1: Training courses | S1: Travel public transport | T1: Mobile connection | U1: Food | V1: Utility Payments | W1: Internet & TV | X1: Household chemicals | Y1: Furniture & utensils | Z1: BedLinen & tablecloth | AA1: Cat food | AB1: Clothing & footwear | AC1: Gym | AD1: Hygiene products | AE1: Medications | AF1: Hairdresser | AG1: Cosmetics & perfumery | AH1: Fuel | AI1: Spare parts | AJ1: Parking | AK1: Washing | AL1: Insurance | AM1: Holidays | AN1: Excursions | AO1: Restaurants | AP1: Hotels | AQ1: Bags, packages, boxes | AR1: Snacks on the way | AS1: Investments Business | AT1: Investments Securities | AU1: Investments Cryptocurrency | AV1: Investments Real estate | AW1: Investments Gold | AX1: Mortgage | AY1: Car Leasing | AZ1: Consumer Credit | BA1: Credit Card | BB1: Goal 1 | BC1: Goal 2 | BD1: Goal 3 | BE1: Goal 4 | BF1: Monthly Plan | BG1: Balance
A2: 45292 | B2: JANUARY | C2: 1 | D2: 550 | E2: 600 | F2: 24 | G2: 43 | H2: 41 | I2: 16 | J2: 36 | K2: 13 | L2: 15 | M2: 4 | N2: 46 | O2: 43 | P2: 34 | Q2: 29 | R2: 23 | S2: 33 | T2: 41 | U2: 24 | V2: 41 | W2: 1 | X2: 11 | Y2: 8 | Z2: 48 | AA2: 23 | AB2: 25 | AC2: 37 | AD2: 31 | AE2: 29 | AF2: 37 | AG2: 14 | AH2: 37 | AI2: 38 | AJ2: 4 | AK2: 7 | AL2: 23 | AM2: 6 | AN2: 12 | AO2: 14 | AP2: 18 | AQ2: 45 | AR2: 23 | AS2: 30 | AT2: 30 | AU2: 17 | AV2: 13 | AW2: 20 | AX2: 32 | AY2: 11 | AZ2: 17 | BA2: 13 | BB2: 24 | BC2: 9 | BD2: 32 | BE2: 26 | BF2: 29000 | BG2: 3800
A3: 45293 | B3: JANUARY | C3: 1 | D3: 551 | E3: 600 | F3: 48 | G3: 24 | H3: 1 | I3: 22 | J3: 23 | K3: 31 | L3: 48 | M3: 17 | N3: 30 | O3: 47 | P3: 27 | Q3: 31 | R3: 12 | S3: 34 | T3: 7 | U3: 6 | V3: 34 | W3: 3 | X3: 48 | Y3: 40 | Z3: 37 | AA3: 34 | AB3: 31 | AC3: 45 | AD3: 20 | AE3: 0 | AF3: 46 | AG3: 4 | AH3: 38 | AI3: 38 | AJ3: 34 | AK3: 6 | AL3: 37 | AM3: 27 | AN3: 31 | AO3: 34 | AP3: 30 | AQ3: 31 | AR3: 20 | AS3: 16 | AT3: 5 | AU3: 44 | AV3: 12 | AW3: 18 | AX3: 31 | AY3: 34 | AZ3: 49 | BA3: 15 | BB3: 31 | BC3: 44 | BD3: 37 | BE3: 9 | BF3: 29550 | BG3: 3812
A4: 45294 | B4: JANUARY | C4: 1 | D4: 553 | E4: 601 | F4: 6 | G4: 29 | H4: 42 | I4: 27 | J4: 27 | K4: 23 | L4: 14 | M4: 3 | N4: 48 | O4: 36 | P4: 23 | Q4: 49 | R4: 37 | S4: 41 | T4: 31 | U4: 32 | V4: 34 | W4: 7 | X4: 38 | Y4: 24 | Z4: 19 | AA4: 22 | AB4: 43 | AC4: 39 | AD4: 26 | AE4: 40 | AF4: 10 | AG4: 30 | AH4: 48 | AI4: 20 | AJ4: 46 | AK4: 32 | AL4: 43 | AM4: 32 | AN4: 47 | AO4: 45 | AP4: 4 | AQ4: 23 | AR4: 46 | AS4: 14 | AT4: 14 | AU4: 26 | AV4: 25 | AW4: 32 | AX4: 11 | AY4: 11 | AZ4: 33 | BA4: 17 | BB4: 27 | BC4: 27 | BD4: 9 | BE4: 10 | BF4: 30101 | BG4: 3824
A5: 45295 | B5: JANUARY | C5: 1 | D5: 554 | E5: 602 | F5: 21 | G5: 27 | H5: 19 | I5: 26 | J5: 11 | K5: 0 | L5: 36 | M5: 49 | N5: 0 | O5: 15 | P5: 15 | Q5: 9 | R5: 10 | S5: 27 | T5: 39 | U5: 42 | V5: 24 | W5: 19 | X5: 40 | Y5: 18 | Z5: 19 | AA5: 30 | AB5: 25 | AC5: 30 | AD5: 2 | AE5: 45 | AF5: 25 | AG5: 1 | AH5: 6 | AI5: 20 | AJ5: 28 | AK5: 37 | AL5: 42 | AM5: 35 | AN5: 35 | AO5: 44 | AP5: 34 | AQ5: 38 | AR5: 36 | AS5: 21 | AT5: 41 | AU5: 37 | AV5: 33 | AW5: 16 | AX5: 13 | AY5: 35 | AZ5: 24 | BA5: 18 | BB5: 41 | BC5: 49 | BD5: 14 | BE5: 41 | BF5: 30652 | BG5: 3836
A6: 45296 | B6: JANUARY | C6: 1 | D6: 556 | E6: 602 | F6: 40 | G6: 9 | H6: 41 | I6: 31 | J6: 9 | K6: 47 | L6: 26 | M6: 43 | N6: 35 | O6: 28 | P6: 34 | Q6: 47 | R6: 20 | S6: 25 | T6: 31 | U6: 12 | V6: 36 | W6: 24 | X6: 48 | Y6: 32 | Z6: 14 | AA6: 40 | AB6: 11 | AC6: 21 | AD6: 33 | AE6: 48 | AF6: 9 | AG6: 43 | AH6: 7 | AI6: 43 | AJ6: 44 | AK6: 35 | AL6: 18 | AM6: 32 | AN6: 17 | AO6: 47 | AP6: 49 | AQ6: 38 | AR6: 2 | AS6: 6 | AT6: 8 | AU6: 24 | AV6: 7 | AW6: 10 | AX6: 43 | AY6: 5 | AZ6: 4 | BA6: 44 | BB6: 9 | BC6: 32 | BD6: 12 | BE6: 22 | BF6: 31202 | BG6: 3848
A7: 45297 | B7: JANUARY | C7: 1 | D7: 558 | E7: 603 | F7: 24 | G7: 20 | H7: 24 | I7: 8 | J7: 23 | K7: 5 | L7: 17 | M7: 43 | N7: 18 | O7: 27 | P7: 19 | Q7: 22 | R7: 38 | S7: 49 | T7: 14 | U7: 8 | V7: 26 | W7: 34 | X7: 32 | Y7: 5 | Z7: 16 | AA7: 46 | AB7: 22 | AC7: 9 | AD7: 15 | AE7: 27 | AF7: 2 | AG7: 40 | AH7: 1 | AI7: 5 | AJ7: 38 | AK7: 30 | AL7: 40 | AM7: 42 | AN7: 18 | AO7: 45 | AP7: 6 | AQ7: 41 | AR7: 1 | AS7: 26 | AT7: 43 | AU7: 6 | AV7: 21 | AW7: 20 | AX7: 8 | AY7: 0 | AZ7: 36 | BA7: 43 | BB7: 25 | BC7: 5 | BD7: 11 | BE7: 46 | BF7: 31753 | BG7: 3860
A8: 45298 | B8: JANUARY | C8: 1 | D8: 559 | E8: 604 | F8: 25 | G8: 41 | H8: 15 | I8: 39 | J8: 17 | K8: 14 | L8: 47 | M8: 30 | N8: 48 | O8: 2 | P8: 20 | Q8: 13 | R8: 10 | S8: 13 | T8: 4 | U8: 20 | V8: 8 | W8: 1 | X8: 48 | Y8: 38 | Z8: 6 | AA8: 11 | AB8: 7 | AC8: 12 | AD8: 25 | AE8: 37 | AF8: 36 | AG8: 15 | AH8: 10 | AI8: 9 | AJ8: 12 | AK8: 29 | AL8: 4 | AM8: 34 | AN8: 35 | AO8: 15 | AP8: 11 | AQ8: 31 | AR8: 33 | AS8: 21 | AT8: 41 | AU8: 39 | AV8: 29 | AW8: 17 | AX8: 27 | AY8: 43 | AZ8: 6 | BA8: 29 | BB8: 36 | BC8: 1 | BD8: 4 | BE8: 28 | BF8: 32304 | BG8: 3872
A9: 45299 | B9: JANUARY | C9: 1 | D9: 561 | E9: 604 | F9: 13 | G9: 22 | H9: 35 | I9: 42 | J9: 45 | K9: 49 | L9: 22 | M9: 17 | N9: 15 | O9: 41 | P9: 7 | Q9: 12 | R9: 8 | S9: 37 | T9: 21 | U9: 43 | V9: 29 | W9: 34 | X9: 24 | Y9: 6 | Z9: 5 | AA9: 21 | AB9: 11 | AC9: 10 | AD9: 29 | AE9: 45 | AF9: 41 | AG9: 48 | AH9: 3 | AI9: 25 | AJ9: 25 | AK9: 24 | AL9: 31 | AM9: 11 | AN9: 23 | AO9: 46 | AP9: 1 | AQ9: 4 | AR9: 40 | AS9: 24 | AT9: 42 | AU9: 47 | AV9: 33 | AW9: 12 | AX9: 26 | AY9: 13 | AZ9: 26 | BA9: 48 | BB9: 14 | BC9: 39 | BD9: 7 | BE9: 14 | BF9: 32854 | BG9: 3884
A10: 45300 | B10: JANUARY | C10: 1 | D10: 563 | E10: 605 | F10: 28 | G10: 41 | H10: 32 | I10: 42 | J10: 26 | K10: 3 | L10: 6 | M10: 37 | N10: 32 | O10: 44 | P10: 30 | Q10: 3 | R10: 7 | S10: 9 | T10: 33 | U10: 29 | V10: 20 | W10: 6 | X10: 29 | Y10: 4 | Z10: 18 | AA10: 16 | AB10: 31 | AC10: 21 | AD10: 20 | AE10: 24 | AF10: 25 | AG10: 6 | AH10: 16 | AI10: 43 | AJ10: 29 | AK10: 18 | AL10: 13 | AM10: 7 | AN10: 8 | AO10: 43 | AP10: 10 | AQ10: 27 | AR10: 21 | AS10: 16 | AT10: 31 | AU10: 26 | AV10: 15 | AW10: 9 | AX10: 33 | AY10: 25 | AZ10: 10 | BA10: 19 | BB10: 43 | BC10: 17 | BD10: 39 | BE10: 15 | BF10: 33405 | BG10: 3896
A11: 45301 | B11: JANUARY | C11: 1 | D11: 564 | E11: 606 | F11: 46 | G11: 11 | H11: 44 | I11: 32 | J11: 26 | K11: 12 | L11: 25 | M11: 16 | N11: 26 | O11: 8 | P11: 45 | Q11: 36 | R11: 42 | S11: 41 | T11: 35 | U11: 33 | V11: 29 | W11: 43 | X11: 20 | Y11: 0 | Z11: 45 | AA11: 34 | AB11: 45 | AC11: 1 | AD11: 41 | AE11: 1 | AF11: 21 | AG11: 5 | AH11: 41 | AI11: 49 | AJ11: 26 | AK11: 30 | AL11: 0 | AM11: 3 | AN11: 41 | AO11: 23 | AP11: 47 | AQ11: 45 | AR11: 33 | AS11: 35 | AT11: 22 | AU11: 6 | AV11: 4 | AW11: 19 | AX11: 37 | AY11: 18 | AZ11: 15 | BA11: 4 | BB11: 7 | BC11: 30 | BD11: 45 | BE11: 43 | BF11: 33956 | BG11: 3908
A12: 45302 | B12: JANUARY | C12: 1 | D12: 566 | E12: 606 | F12: 3 | G12: 33 | H12: 17 | I12: 25 | J12: 38 | K12: 8 | L12: 25 | M12: 34 | N12: 32 | O12: 6 | P12: 40 | Q12: 44 | R12: 17 | S12: 18 | T12: 8 | U12: 49 | V12: 23 | W12: 44 | X12: 40 | Y12: 0 | Z12: 15 | AA12: 11 | AB12: 20 | AC12: 38 | AD12: 6 | AE12: 42 | AF12: 19 | AG12: 28 | AH12: 22 | AI12: 28 | AJ12: 16 | AK12: 9 | AL12: 23 | AM12: 48 | AN12: 11 | AO12: 17 | AP12: 14 | AQ12: 0 | AR12: 44 | AS12: 22 | AT12: 46 | AU12: 25 | AV12: 35 | AW12: 23 | AX12: 43 | AY12: 2 | AZ12: 18 | BA12: 36 | BB12: 22 | BC12: 33 | BD12: 11 | BE12: 38 | BF12: 34506 | BG12: 3920
A13: 45303 | B13: JANUARY | C13: 1 | D13: 568 | E13: 607 | F13: 37 | G13: 11 | H13: 44 | I13: 38 | J13: 3 | K13: 41 | L13: 49 | M13: 20 | N13: 9 | O13: 17 | P13: 3 | Q13: 45 | R13: 34 | S13: 49 | T13: 21 | U13: 37 | V13: 24 | W13: 19 | X13: 49 | Y13: 27 | Z13: 11 | AA13: 34 | AB13: 3 | AC13: 42 | AD13: 25 | AE13: 24 | AF13: 33 | AG13: 24 | AH13: 33 | AI13: 46 | AJ13: 22 | AK13: 14 | AL13: 32 | AM13: 44 | AN13: 23 | AO13: 45 | AP13: 13 | AQ13: 14 | AR13: 26 | AS13: 18 | AT13: 29 | AU13: 19 | AV13: 14 | AW13: 7 | AX13: 12 | AY13: 47 | AZ13: 7 | BA13: 29 | BB13: 32 | BC13: 33 | BD13: 9 | BE13: 25 | BF13: 35057 | BG13: 3932
... A367: 45657 | B367: DECEMBER | C367: 12 | D367: 1150 | E367: 850 | F367: 25 | G367: 48 | H367: 5 | I367: 30 | J367: 36 | K367: 11 | L367: 39 | M367: 4 | N367: 30 | O367: 24 | P367: 22 | Q367: 8 | R367: 13 | S367: 23 | T367: 16 | U367: 25 | V367: 43 | W367: 31 | X367: 10 | Y367: 3 | Z367: 44 | AA367: 31 | AB367: 19 | AC367: 1 | AD367: 1 | AE367: 23 | AF367: 13 | AG367: 27 | AH367: 30 | AI367: 23 | AJ367: 19 | AK367: 14 | AL367: 37 | AM367: 38 | AN367: 49 | AO367: 32 | AP367: 24 | AQ367: 14 | AR367: 23 | AS367: 14 | AT367: 24 | AU367: 31 | AV367: 12 | AW367: 2 | AX367: 6 | AY367: 33 | AZ367: 44 | BA367: 28 | BB367: 9 | BC367: 30 | BD367: 32 | BE367: 26 | BF367: 230000 | BG367: 8200

Sheet Sheet2
C4: #374AEC | F4: $#,##0;-$#,##0;0
C5: #1B2399
C6: #7C93FD
C7: #4641D1
C8: #0093CE
C9: #2069F0
C10: #9933FF
C13: #808AEC
C14: #4A59E4
C15: #FF00FF
C18: #0070B1
C19: #00B7D2
C20: #3A5CE2
... C35: #FF00FF
